[2016-08-18 21:03:33 +0800] [9639] [INFO] Starting gunicorn 19.6.0
[2016-08-18 21:03:33 +0800] [9639] [INFO] Listening at: http://127.0.0.1:8000 (9639)
[2016-08-18 21:03:33 +0800] [9639] [INFO] Using worker: sync
[2016-08-18 21:03:33 +0800] [9642] [INFO] Booting worker with pid: 9642
[2016-08-18 21:03:49 +0800] [9642] [ERROR] Error handling request /
Traceback (most recent call last):
  File "/usr/local/lib/python3.4/dist-packages/django/core/handlers/exception.py", line 39, in inner
    response = get_response(request)
  File "/usr/local/lib/python3.4/dist-packages/django/core/handlers/base.py", line 244, in _legacy_get_response
    response = middleware_method(request)
  File "/usr/local/lib/python3.4/dist-packages/django/middleware/locale.py", line 24, in process_request
    i18n_patterns_used, prefixed_default_language = is_language_prefix_patterns_used(urlconf)
  File "/usr/lib/python3.4/functools.py", line 448, in wrapper
    result = user_function(*args, **kwds)
  File "/usr/local/lib/python3.4/dist-packages/django/conf/urls/i18n.py", line 29, in is_language_prefix_patterns_used
    for url_pattern in get_resolver(urlconf).url_patterns:
  File "/usr/local/lib/python3.4/dist-packages/django/utils/functional.py", line 35, in __get__
    res = instance.__dict__[self.name] = self.func(instance)
  File "/usr/local/lib/python3.4/dist-packages/django/urls/resolvers.py", line 310, in url_patterns
    patterns = getattr(self.urlconf_module, "urlpatterns", self.urlconf_module)
  File "/usr/local/lib/python3.4/dist-packages/django/utils/functional.py", line 35, in __get__
    res = instance.__dict__[self.name] = self.func(instance)
  File "/usr/local/lib/python3.4/dist-packages/django/urls/resolvers.py", line 303, in urlconf_module
    return import_module(self.urlconf_name)
  File "/usr/lib/python3.4/importlib/__init__.py", line 109, in import_module
    return _bootstrap._gcd_import(name[level:], package, level)
  File "<frozen importlib._bootstrap>", line 2254, in _gcd_import
  File "<frozen importlib._bootstrap>", line 2237, in _find_and_load
  File "<frozen importlib._bootstrap>", line 2226, in _find_and_load_unlocked
  File "<frozen importlib._bootstrap>", line 1200, in _load_unlocked
  File "<frozen importlib._bootstrap>", line 1129, in _exec
  File "<frozen importlib._bootstrap>", line 1471, in exec_module
  File "<frozen importlib._bootstrap>", line 321, in _call_with_frames_removed
  File "/home/TravelBlog/MyTravel/urls.py", line 19, in <module>
    from MyTravel.views import *
  File "/home/TravelBlog/MyTravel/views.py", line 2, in <module>
    from ipware.ip import get_real_ip, get_ip, get_trusted_ip
ImportError: No module named 'ipware'

During handling of the above exception, another exception occurred:

Traceback (most recent call last):
  File "/usr/local/lib/python3.4/dist-packages/gunicorn/workers/sync.py", line 135, in handle
    self.handle_request(listener, req, client, addr)
  File "/usr/local/lib/python3.4/dist-packages/gunicorn/workers/sync.py", line 176, in handle_request
    respiter = self.wsgi(environ, resp.start_response)
  File "/usr/local/lib/python3.4/dist-packages/django/core/handlers/wsgi.py", line 170, in __call__
    response = self.get_response(request)
  File "/usr/local/lib/python3.4/dist-packages/django/core/handlers/base.py", line 124, in get_response
    response = self._middleware_chain(request)
  File "/usr/local/lib/python3.4/dist-packages/django/core/handlers/exception.py", line 41, in inner
    response = response_for_exception(request, exc)
  File "/usr/local/lib/python3.4/dist-packages/django/core/handlers/exception.py", line 86, in response_for_exception
    response = handle_uncaught_exception(request, get_resolver(get_urlconf()), sys.exc_info())
  File "/usr/local/lib/python3.4/dist-packages/django/core/handlers/exception.py", line 131, in handle_uncaught_exception
    if resolver.urlconf_module is None:
  File "/usr/local/lib/python3.4/dist-packages/django/utils/functional.py", line 35, in __get__
    res = instance.__dict__[self.name] = self.func(instance)
  File "/usr/local/lib/python3.4/dist-packages/django/urls/resolvers.py", line 303, in urlconf_module
    return import_module(self.urlconf_name)
  File "/usr/lib/python3.4/importlib/__init__.py", line 109, in import_module
    return _bootstrap._gcd_import(name[level:], package, level)
  File "<frozen importlib._bootstrap>", line 2254, in _gcd_import
  File "<frozen importlib._bootstrap>", line 2237, in _find_and_load
  File "<frozen importlib._bootstrap>", line 2226, in _find_and_load_unlocked
  File "<frozen importlib._bootstrap>", line 1200, in _load_unlocked
  File "<frozen importlib._bootstrap>", line 1129, in _exec
  File "<frozen importlib._bootstrap>", line 1471, in exec_module
  File "<frozen importlib._bootstrap>", line 321, in _call_with_frames_removed
  File "/home/TravelBlog/MyTravel/urls.py", line 19, in <module>
    from MyTravel.views import *
  File "/home/TravelBlog/MyTravel/views.py", line 2, in <module>
    from ipware.ip import get_real_ip, get_ip, get_trusted_ip
ImportError: No module named 'ipware'
[2016-08-18 21:03:52 +0800] [9642] [ERROR] Error handling request /
Traceback (most recent call last):
  File "/usr/local/lib/python3.4/dist-packages/django/core/handlers/exception.py", line 39, in inner
    response = get_response(request)
  File "/usr/local/lib/python3.4/dist-packages/django/core/handlers/base.py", line 244, in _legacy_get_response
    response = middleware_method(request)
  File "/usr/local/lib/python3.4/dist-packages/django/middleware/locale.py", line 24, in process_request
    i18n_patterns_used, prefixed_default_language = is_language_prefix_patterns_used(urlconf)
  File "/usr/lib/python3.4/functools.py", line 448, in wrapper
    result = user_function(*args, **kwds)
  File "/usr/local/lib/python3.4/dist-packages/django/conf/urls/i18n.py", line 29, in is_language_prefix_patterns_used
    for url_pattern in get_resolver(urlconf).url_patterns:
  File "/usr/local/lib/python3.4/dist-packages/django/utils/functional.py", line 35, in __get__
    res = instance.__dict__[self.name] = self.func(instance)
  File "/usr/local/lib/python3.4/dist-packages/django/urls/resolvers.py", line 310, in url_patterns
    patterns = getattr(self.urlconf_module, "urlpatterns", self.urlconf_module)
  File "/usr/local/lib/python3.4/dist-packages/django/utils/functional.py", line 35, in __get__
    res = instance.__dict__[self.name] = self.func(instance)
  File "/usr/local/lib/python3.4/dist-packages/django/urls/resolvers.py", line 303, in urlconf_module
    return import_module(self.urlconf_name)
  File "/usr/lib/python3.4/importlib/__init__.py", line 109, in import_module
    return _bootstrap._gcd_import(name[level:], package, level)
  File "<frozen importlib._bootstrap>", line 2254, in _gcd_import
  File "<frozen importlib._bootstrap>", line 2237, in _find_and_load
  File "<frozen importlib._bootstrap>", line 2226, in _find_and_load_unlocked
  File "<frozen importlib._bootstrap>", line 1200, in _load_unlocked
  File "<frozen importlib._bootstrap>", line 1129, in _exec
  File "<frozen importlib._bootstrap>", line 1471, in exec_module
  File "<frozen importlib._bootstrap>", line 321, in _call_with_frames_removed
  File "/home/TravelBlog/MyTravel/urls.py", line 19, in <module>
    from MyTravel.views import *
  File "/home/TravelBlog/MyTravel/views.py", line 2, in <module>
    from ipware.ip import get_real_ip, get_ip, get_trusted_ip
ImportError: No module named 'ipware'

During handling of the above exception, another exception occurred:

Traceback (most recent call last):
  File "/usr/local/lib/python3.4/dist-packages/gunicorn/workers/sync.py", line 135, in handle
    self.handle_request(listener, req, client, addr)
  File "/usr/local/lib/python3.4/dist-packages/gunicorn/workers/sync.py", line 176, in handle_request
    respiter = self.wsgi(environ, resp.start_response)
  File "/usr/local/lib/python3.4/dist-packages/django/core/handlers/wsgi.py", line 170, in __call__
    response = self.get_response(request)
  File "/usr/local/lib/python3.4/dist-packages/django/core/handlers/base.py", line 124, in get_response
    response = self._middleware_chain(request)
  File "/usr/local/lib/python3.4/dist-packages/django/core/handlers/exception.py", line 41, in inner
    response = response_for_exception(request, exc)
  File "/usr/local/lib/python3.4/dist-packages/django/core/handlers/exception.py", line 86, in response_for_exception
    response = handle_uncaught_exception(request, get_resolver(get_urlconf()), sys.exc_info())
  File "/usr/local/lib/python3.4/dist-packages/django/core/handlers/exception.py", line 131, in handle_uncaught_exception
    if resolver.urlconf_module is None:
  File "/usr/local/lib/python3.4/dist-packages/django/utils/functional.py", line 35, in __get__
    res = instance.__dict__[self.name] = self.func(instance)
  File "/usr/local/lib/python3.4/dist-packages/django/urls/resolvers.py", line 303, in urlconf_module
    return import_module(self.urlconf_name)
  File "/usr/lib/python3.4/importlib/__init__.py", line 109, in import_module
    return _bootstrap._gcd_import(name[level:], package, level)
  File "<frozen importlib._bootstrap>", line 2254, in _gcd_import
  File "<frozen importlib._bootstrap>", line 2237, in _find_and_load
  File "<frozen importlib._bootstrap>", line 2226, in _find_and_load_unlocked
  File "<frozen importlib._bootstrap>", line 1200, in _load_unlocked
  File "<frozen importlib._bootstrap>", line 1129, in _exec
  File "<frozen importlib._bootstrap>", line 1471, in exec_module
  File "<frozen importlib._bootstrap>", line 321, in _call_with_frames_removed
  File "/home/TravelBlog/MyTravel/urls.py", line 19, in <module>
    from MyTravel.views import *
  File "/home/TravelBlog/MyTravel/views.py", line 2, in <module>
    from ipware.ip import get_real_ip, get_ip, get_trusted_ip
ImportError: No module named 'ipware'
[2016-08-18 21:04:08 +0800] [9642] [ERROR] Error handling request /
Traceback (most recent call last):
  File "/usr/local/lib/python3.4/dist-packages/django/core/handlers/exception.py", line 39, in inner
    response = get_response(request)
  File "/usr/local/lib/python3.4/dist-packages/django/core/handlers/base.py", line 244, in _legacy_get_response
    response = middleware_method(request)
  File "/usr/local/lib/python3.4/dist-packages/django/middleware/locale.py", line 24, in process_request
    i18n_patterns_used, prefixed_default_language = is_language_prefix_patterns_used(urlconf)
  File "/usr/lib/python3.4/functools.py", line 448, in wrapper
    result = user_function(*args, **kwds)
  File "/usr/local/lib/python3.4/dist-packages/django/conf/urls/i18n.py", line 29, in is_language_prefix_patterns_used
    for url_pattern in get_resolver(urlconf).url_patterns:
  File "/usr/local/lib/python3.4/dist-packages/django/utils/functional.py", line 35, in __get__
    res = instance.__dict__[self.name] = self.func(instance)
  File "/usr/local/lib/python3.4/dist-packages/django/urls/resolvers.py", line 310, in url_patterns
    patterns = getattr(self.urlconf_module, "urlpatterns", self.urlconf_module)
  File "/usr/local/lib/python3.4/dist-packages/django/utils/functional.py", line 35, in __get__
    res = instance.__dict__[self.name] = self.func(instance)
  File "/usr/local/lib/python3.4/dist-packages/django/urls/resolvers.py", line 303, in urlconf_module
    return import_module(self.urlconf_name)
  File "/usr/lib/python3.4/importlib/__init__.py", line 109, in import_module
    return _bootstrap._gcd_import(name[level:], package, level)
  File "<frozen importlib._bootstrap>", line 2254, in _gcd_import
  File "<frozen importlib._bootstrap>", line 2237, in _find_and_load
  File "<frozen importlib._bootstrap>", line 2226, in _find_and_load_unlocked
  File "<frozen importlib._bootstrap>", line 1200, in _load_unlocked
  File "<frozen importlib._bootstrap>", line 1129, in _exec
  File "<frozen importlib._bootstrap>", line 1471, in exec_module
  File "<frozen importlib._bootstrap>", line 321, in _call_with_frames_removed
  File "/home/TravelBlog/MyTravel/urls.py", line 19, in <module>
    from MyTravel.views import *
  File "/home/TravelBlog/MyTravel/views.py", line 2, in <module>
    from ipware.ip import get_real_ip, get_ip, get_trusted_ip
ImportError: No module named 'ipware'

During handling of the above exception, another exception occurred:

Traceback (most recent call last):
  File "/usr/local/lib/python3.4/dist-packages/gunicorn/workers/sync.py", line 135, in handle
    self.handle_request(listener, req, client, addr)
  File "/usr/local/lib/python3.4/dist-packages/gunicorn/workers/sync.py", line 176, in handle_request
    respiter = self.wsgi(environ, resp.start_response)
  File "/usr/local/lib/python3.4/dist-packages/django/core/handlers/wsgi.py", line 170, in __call__
    response = self.get_response(request)
  File "/usr/local/lib/python3.4/dist-packages/django/core/handlers/base.py", line 124, in get_response
    response = self._middleware_chain(request)
  File "/usr/local/lib/python3.4/dist-packages/django/core/handlers/exception.py", line 41, in inner
    response = response_for_exception(request, exc)
  File "/usr/local/lib/python3.4/dist-packages/django/core/handlers/exception.py", line 86, in response_for_exception
    response = handle_uncaught_exception(request, get_resolver(get_urlconf()), sys.exc_info())
  File "/usr/local/lib/python3.4/dist-packages/django/core/handlers/exception.py", line 131, in handle_uncaught_exception
    if resolver.urlconf_module is None:
  File "/usr/local/lib/python3.4/dist-packages/django/utils/functional.py", line 35, in __get__
    res = instance.__dict__[self.name] = self.func(instance)
  File "/usr/local/lib/python3.4/dist-packages/django/urls/resolvers.py", line 303, in urlconf_module
    return import_module(self.urlconf_name)
  File "/usr/lib/python3.4/importlib/__init__.py", line 109, in import_module
    return _bootstrap._gcd_import(name[level:], package, level)
  File "<frozen importlib._bootstrap>", line 2254, in _gcd_import
  File "<frozen importlib._bootstrap>", line 2237, in _find_and_load
  File "<frozen importlib._bootstrap>", line 2226, in _find_and_load_unlocked
  File "<frozen importlib._bootstrap>", line 1200, in _load_unlocked
  File "<frozen importlib._bootstrap>", line 1129, in _exec
  File "<frozen importlib._bootstrap>", line 1471, in exec_module
  File "<frozen importlib._bootstrap>", line 321, in _call_with_frames_removed
  File "/home/TravelBlog/MyTravel/urls.py", line 19, in <module>
    from MyTravel.views import *
  File "/home/TravelBlog/MyTravel/views.py", line 2, in <module>
    from ipware.ip import get_real_ip, get_ip, get_trusted_ip
ImportError: No module named 'ipware'
[2016-08-18 21:04:26 +0800] [9639] [INFO] Handling signal: int
[2016-08-18 21:04:26 +0800] [9642] [INFO] Worker exiting (pid: 9642)
[2016-08-18 21:04:26 +0800] [9639] [INFO] Shutting down: Master
[2016-08-18 21:34:58 +0800] [10308] [INFO] Starting gunicorn 19.6.0
[2016-08-18 21:34:58 +0800] [10308] [INFO] Listening at: http://127.0.0.1:8000 (10308)
[2016-08-18 21:34:58 +0800] [10308] [INFO] Using worker: sync
[2016-08-18 21:34:58 +0800] [10311] [INFO] Booting worker with pid: 10311
[2016-08-19 21:30:17 +0800] [10311] [INFO] Worker reloading: /home/TravelBlog/MyTravel/settings.py modified
[2016-08-19 21:30:31 +0800] [10311] [INFO] Worker exiting (pid: 10311)
[2016-08-19 21:30:31 +0800] [14027] [INFO] Booting worker with pid: 14027
[2016-08-19 21:32:18 +0800] [14033] [INFO] Starting gunicorn 19.6.0
[2016-08-19 21:32:18 +0800] [14033] [ERROR] Connection in use: ('127.0.0.1', 8000)
[2016-08-19 21:32:18 +0800] [14033] [ERROR] Retrying in 1 second.
[2016-08-19 21:32:19 +0800] [14033] [ERROR] Connection in use: ('127.0.0.1', 8000)
[2016-08-19 21:32:19 +0800] [14033] [ERROR] Retrying in 1 second.
[2016-08-19 21:32:20 +0800] [14033] [ERROR] Connection in use: ('127.0.0.1', 8000)
[2016-08-19 21:32:20 +0800] [14033] [ERROR] Retrying in 1 second.
[2016-08-19 21:32:21 +0800] [14033] [ERROR] Connection in use: ('127.0.0.1', 8000)
[2016-08-19 21:32:21 +0800] [14033] [ERROR] Retrying in 1 second.
[2016-08-19 21:32:22 +0800] [14033] [ERROR] Connection in use: ('127.0.0.1', 8000)
[2016-08-19 21:32:22 +0800] [14033] [ERROR] Retrying in 1 second.
[2016-08-19 21:32:23 +0800] [14033] [ERROR] Can't connect to ('127.0.0.1', 8000)
[2016-08-19 21:36:52 +0800] [14027] [INFO] Worker reloading: /home/TravelBlog/MyTravel/settings.py modified
[2016-08-19 21:36:56 +0800] [14064] [INFO] Starting gunicorn 19.6.0
[2016-08-19 21:36:56 +0800] [14064] [ERROR] Connection in use: ('127.0.0.1', 8000)
[2016-08-19 21:36:56 +0800] [14064] [ERROR] Retrying in 1 second.
[2016-08-19 21:36:57 +0800] [14064] [ERROR] Connection in use: ('127.0.0.1', 8000)
[2016-08-19 21:36:57 +0800] [14064] [ERROR] Retrying in 1 second.
[2016-08-19 21:36:58 +0800] [14064] [ERROR] Connection in use: ('127.0.0.1', 8000)
[2016-08-19 21:36:58 +0800] [14064] [ERROR] Retrying in 1 second.
[2016-08-19 21:36:59 +0800] [14064] [ERROR] Connection in use: ('127.0.0.1', 8000)
[2016-08-19 21:36:59 +0800] [14064] [ERROR] Retrying in 1 second.
[2016-08-19 21:37:00 +0800] [14064] [ERROR] Connection in use: ('127.0.0.1', 8000)
[2016-08-19 21:37:00 +0800] [14064] [ERROR] Retrying in 1 second.
[2016-08-19 21:37:01 +0800] [14064] [ERROR] Can't connect to ('127.0.0.1', 8000)
[2016-08-19 21:37:02 +0800] [14027] [INFO] Worker exiting (pid: 14027)
[2016-08-19 21:37:02 +0800] [14067] [INFO] Booting worker with pid: 14067
[2016-08-19 21:37:03 +0800] [14067] [ERROR] Exception in worker process
Traceback (most recent call last):
  File "/usr/local/lib/python3.4/dist-packages/gunicorn/arbiter.py", line 557, in spawn_worker
    worker.init_process()
  File "/usr/local/lib/python3.4/dist-packages/gunicorn/workers/base.py", line 126, in init_process
    self.load_wsgi()
  File "/usr/local/lib/python3.4/dist-packages/gunicorn/workers/base.py", line 136, in load_wsgi
    self.wsgi = self.app.wsgi()
  File "/usr/local/lib/python3.4/dist-packages/gunicorn/app/base.py", line 67, in wsgi
    self.callable = self.load()
  File "/usr/local/lib/python3.4/dist-packages/gunicorn/app/wsgiapp.py", line 65, in load
    return self.load_wsgiapp()
  File "/usr/local/lib/python3.4/dist-packages/gunicorn/app/wsgiapp.py", line 52, in load_wsgiapp
    return util.import_app(self.app_uri)
  File "/usr/local/lib/python3.4/dist-packages/gunicorn/util.py", line 357, in import_app
    __import__(module)
  File "/home/TravelBlog/MyTravel/wsgi.py", line 16, in <module>
    application = get_wsgi_application()
  File "/usr/local/lib/python3.4/dist-packages/django/core/wsgi.py", line 13, in get_wsgi_application
    django.setup(set_prefix=False)
  File "/usr/local/lib/python3.4/dist-packages/django/__init__.py", line 22, in setup
    configure_logging(settings.LOGGING_CONFIG, settings.LOGGING)
  File "/usr/local/lib/python3.4/dist-packages/django/conf/__init__.py", line 53, in __getattr__
    self._setup(name)
  File "/usr/local/lib/python3.4/dist-packages/django/conf/__init__.py", line 41, in _setup
    self._wrapped = Settings(settings_module)
  File "/usr/local/lib/python3.4/dist-packages/django/conf/__init__.py", line 97, in __init__
    mod = importlib.import_module(self.SETTINGS_MODULE)
  File "/usr/lib/python3.4/importlib/__init__.py", line 109, in import_module
    return _bootstrap._gcd_import(name[level:], package, level)
  File "/home/TravelBlog/MyTravel/settings.py", line 152, in <module>
    SUMMERNOTE_CONFIG += {
NameError: name 'SUMMERNOTE_CONFIG' is not defined
[2016-08-19 21:37:03 +0800] [14067] [INFO] Worker exiting (pid: 14067)
[2016-08-19 21:37:03 +0800] [10308] [INFO] Shutting down: Master
[2016-08-19 21:37:03 +0800] [10308] [INFO] Reason: Worker failed to boot.
[2016-08-19 21:38:22 +0800] [14078] [INFO] Starting gunicorn 19.6.0
[2016-08-19 21:38:22 +0800] [14078] [INFO] Listening at: http://127.0.0.1:8000 (14078)
[2016-08-19 21:38:22 +0800] [14078] [INFO] Using worker: sync
[2016-08-19 21:38:22 +0800] [14081] [INFO] Booting worker with pid: 14081
[2016-08-19 21:43:11 +0800] [14081] [INFO] Worker reloading: /home/TravelBlog/MyTravel/settings.py modified
[2016-08-19 21:43:14 +0800] [14102] [INFO] Starting gunicorn 19.6.0
[2016-08-19 21:43:14 +0800] [14102] [ERROR] Connection in use: ('127.0.0.1', 8000)
[2016-08-19 21:43:14 +0800] [14102] [ERROR] Retrying in 1 second.
[2016-08-19 21:43:14 +0800] [14081] [INFO] Worker exiting (pid: 14081)
[2016-08-19 21:43:14 +0800] [14105] [INFO] Booting worker with pid: 14105
[2016-08-19 21:43:15 +0800] [14102] [ERROR] Connection in use: ('127.0.0.1', 8000)
[2016-08-19 21:43:15 +0800] [14102] [ERROR] Retrying in 1 second.
[2016-08-19 21:43:16 +0800] [14102] [ERROR] Connection in use: ('127.0.0.1', 8000)
[2016-08-19 21:43:16 +0800] [14102] [ERROR] Retrying in 1 second.
[2016-08-19 21:43:17 +0800] [14102] [ERROR] Connection in use: ('127.0.0.1', 8000)
[2016-08-19 21:43:17 +0800] [14102] [ERROR] Retrying in 1 second.
[2016-08-19 21:43:18 +0800] [14102] [ERROR] Connection in use: ('127.0.0.1', 8000)
[2016-08-19 21:43:18 +0800] [14102] [ERROR] Retrying in 1 second.
[2016-08-19 21:43:19 +0800] [14102] [ERROR] Can't connect to ('127.0.0.1', 8000)
Internal Server Error: /summernote/upload_attachment/
Traceback (most recent call last):
  File "/usr/local/lib/python3.4/dist-packages/django/core/handlers/exception.py", line 39, in inner
    response = get_response(request)
  File "/usr/local/lib/python3.4/dist-packages/django/core/handlers/base.py", line 249, in _legacy_get_response
    response = self._get_response(request)
  File "/usr/local/lib/python3.4/dist-packages/django/core/handlers/base.py", line 187, in _get_response
    response = self.process_exception_by_middleware(e, request)
  File "/usr/local/lib/python3.4/dist-packages/django/core/handlers/base.py", line 185, in _get_response
    response = wrapped_callback(request, *callback_args, **callback_kwargs)
  File "/usr/local/lib/python3.4/dist-packages/django_summernote/views.py", line 53, in upload_attachment
    if file.size > summernote_config['attachment_filesize_limit']:
TypeError: unorderable types: int() > str()
Internal Server Error: /summernote/upload_attachment/
Traceback (most recent call last):
  File "/usr/local/lib/python3.4/dist-packages/django/core/handlers/exception.py", line 39, in inner
    response = get_response(request)
  File "/usr/local/lib/python3.4/dist-packages/django/core/handlers/base.py", line 249, in _legacy_get_response
    response = self._get_response(request)
  File "/usr/local/lib/python3.4/dist-packages/django/core/handlers/base.py", line 187, in _get_response
    response = self.process_exception_by_middleware(e, request)
  File "/usr/local/lib/python3.4/dist-packages/django/core/handlers/base.py", line 185, in _get_response
    response = wrapped_callback(request, *callback_args, **callback_kwargs)
  File "/usr/local/lib/python3.4/dist-packages/django_summernote/views.py", line 53, in upload_attachment
    if file.size > summernote_config['attachment_filesize_limit']:
TypeError: unorderable types: int() > str()
[2016-08-19 21:44:53 +0800] [14105] [INFO] Worker reloading: /home/TravelBlog/MyTravel/settings.py modified
[2016-08-19 21:44:55 +0800] [14111] [INFO] Starting gunicorn 19.6.0
[2016-08-19 21:44:55 +0800] [14111] [ERROR] Connection in use: ('127.0.0.1', 8000)
[2016-08-19 21:44:55 +0800] [14111] [ERROR] Retrying in 1 second.
[2016-08-19 21:44:56 +0800] [14111] [ERROR] Connection in use: ('127.0.0.1', 8000)
[2016-08-19 21:44:56 +0800] [14111] [ERROR] Retrying in 1 second.
[2016-08-19 21:44:57 +0800] [14105] [INFO] Worker exiting (pid: 14105)
[2016-08-19 21:44:57 +0800] [14114] [INFO] Booting worker with pid: 14114
[2016-08-19 21:44:57 +0800] [14111] [ERROR] Connection in use: ('127.0.0.1', 8000)
[2016-08-19 21:44:57 +0800] [14111] [ERROR] Retrying in 1 second.
[2016-08-19 21:44:58 +0800] [14111] [ERROR] Connection in use: ('127.0.0.1', 8000)
[2016-08-19 21:44:58 +0800] [14111] [ERROR] Retrying in 1 second.
[2016-08-19 21:44:59 +0800] [14111] [ERROR] Connection in use: ('127.0.0.1', 8000)
[2016-08-19 21:44:59 +0800] [14111] [ERROR] Retrying in 1 second.
[2016-08-19 21:45:00 +0800] [14111] [ERROR] Can't connect to ('127.0.0.1', 8000)
[2016-08-19 21:47:18 +0800] [14114] [INFO] Worker reloading: /home/TravelBlog/MyTravel/settings.py modified
[2016-08-19 21:47:20 +0800] [14123] [INFO] Starting gunicorn 19.6.0
[2016-08-19 21:47:20 +0800] [14123] [ERROR] Connection in use: ('127.0.0.1', 8000)
[2016-08-19 21:47:20 +0800] [14123] [ERROR] Retrying in 1 second.
[2016-08-19 21:47:21 +0800] [14123] [ERROR] Connection in use: ('127.0.0.1', 8000)
[2016-08-19 21:47:21 +0800] [14123] [ERROR] Retrying in 1 second.
[2016-08-19 21:47:22 +0800] [14123] [ERROR] Connection in use: ('127.0.0.1', 8000)
[2016-08-19 21:47:22 +0800] [14123] [ERROR] Retrying in 1 second.
[2016-08-19 21:47:22 +0800] [14114] [INFO] Worker exiting (pid: 14114)
[2016-08-19 21:47:22 +0800] [14126] [INFO] Booting worker with pid: 14126
[2016-08-19 21:47:23 +0800] [14123] [ERROR] Connection in use: ('127.0.0.1', 8000)
[2016-08-19 21:47:23 +0800] [14123] [ERROR] Retrying in 1 second.
[2016-08-19 21:47:24 +0800] [14123] [ERROR] Connection in use: ('127.0.0.1', 8000)
[2016-08-19 21:47:24 +0800] [14123] [ERROR] Retrying in 1 second.
[2016-08-19 21:47:25 +0800] [14123] [ERROR] Can't connect to ('127.0.0.1', 8000)
[2016-08-19 21:48:06 +0800] [14126] [INFO] Worker reloading: /home/TravelBlog/MyTravel/settings.py modified
[2016-08-19 21:48:08 +0800] [14147] [INFO] Starting gunicorn 19.6.0
[2016-08-19 21:48:08 +0800] [14147] [ERROR] Connection in use: ('127.0.0.1', 8000)
[2016-08-19 21:48:08 +0800] [14147] [ERROR] Retrying in 1 second.
[2016-08-19 21:48:09 +0800] [14147] [ERROR] Connection in use: ('127.0.0.1', 8000)
[2016-08-19 21:48:09 +0800] [14147] [ERROR] Retrying in 1 second.
[2016-08-19 21:48:10 +0800] [14147] [ERROR] Connection in use: ('127.0.0.1', 8000)
[2016-08-19 21:48:10 +0800] [14147] [ERROR] Retrying in 1 second.
[2016-08-19 21:48:10 +0800] [14126] [INFO] Worker exiting (pid: 14126)
[2016-08-19 21:48:10 +0800] [14150] [INFO] Booting worker with pid: 14150
[2016-08-19 21:48:11 +0800] [14147] [ERROR] Connection in use: ('127.0.0.1', 8000)
[2016-08-19 21:48:11 +0800] [14147] [ERROR] Retrying in 1 second.
[2016-08-19 21:48:12 +0800] [14147] [ERROR] Connection in use: ('127.0.0.1', 8000)
[2016-08-19 21:48:12 +0800] [14147] [ERROR] Retrying in 1 second.
[2016-08-19 21:48:13 +0800] [14147] [ERROR] Can't connect to ('127.0.0.1', 8000)
Not Found: /manager/html
Not Found: /azenv.php
Not Found: /azenv.php
Not Found: /av.php
Not Found: /av.php
Not Found: /testproxy.php
Not Found: /azenv.php
Not Found: /cache/global/img/gs.gif
